<robot
  name="left_wheel" xmlns:xacro="http://www.ros.org/wiki/xacro">

  <joint name="wheel_left_joint" type="continuous">
      <origin xyz="0 0.2495 0.2945"
              rpy="0 0 0"/>
      <axis xyz="0 0 1"/>
      <parent link="base_link"/>
      <child link="wheel_left" />
  </joint>

  <link
    name="wheel_left">
    <inertial>
      <origin
        xyz="-7.9420377562674E-06 ${0.24951709372592-0.2495} ${-0.288056803732584-0.2945}"
        rpy="0 0 0" />
      <mass
        value="0.443396701886305" />
      <inertia
        ixx="0.000711221648918028"
        ixy="5.67486914934626E-08"
        ixz="-1.27045178218059E-07"
        iyy="0.000711318140470388"
        iyz="2.73440585716329E-07"
        izz="0.00115225918118374" />
    </inertial>

    <visual>
      <origin
        xyz="0 -0.2495 -0.2945"
        rpy="0 0 0" />
      <geometry>
        <mesh
          filename="package://hansbase_description/urdf/agv/left_wheel/meshes/left_wheel.STL" />
      </geometry>
      <material
        name="">
        <color
          rgba="${255/255} ${108/255} ${10/255} 1.0" />
      </material>
    </visual>
    <collision>
      <origin
        xyz="0 -0.2495 -0.2945"
        rpy="0 0 0" />
      <geometry>
        <mesh
          filename="package://hansbase_description/urdf/agv/left_wheel/meshes/left_wheel.STL" />
      </geometry>
    </collision>
  </link>
</robot>
